<?xml version="1.0"?>
<robot name="dh_robot">

  <link name="world" />

  <!-- Link 1 -->
  
  <link name="link1">
    <visual>
      <origin xyz="0 0 0.5" rpy="0 0 0" />
      <geometry>
        <box size="0.1 0.1 0.1"/>
      </geometry>
      <material name="blue">
        <color rgba="0 0 1 1"/>
      </material>
    </visual>
    <collision>
      <geometry>
        <box size="0.1 0.1 0.5"/>
      </geometry>
    </collision>
    <inertial>
      <mass value="1.0"/>
      <inertia ixx="0.01" ixy="0.0" ixz="0.0" iyy="0.01" iyz="0.0" izz="0.01"/>
    </inertial>
  </link>

  <!-- Joint 1 -->
  <joint name="joint1" type="prismatic">
    <parent link="world"/>
    <child link="link1"/>
    <origin xyz="0 0 0" rpy="0 0 0"/>
    <axis xyz="0 0 1"/>
    <limit lower="0.0" upper="1.0" effort="10.0" velocity="0.5"/>
  </joint>

  <!-- Link 2 -->
  <link name="link2">
    <visual>
      <origin xyz="0 0 0" rpy="0 0 0" />
      <!--geometry>
        <box size="0.1 0.1 0.5"/>
      </geometry>
      <material name="red">
        <color rgba="1 0 0 1"/>
      </material-->
    </visual>
    <collision>
      <geometry>
        <box size="0.1 0.1 0.5"/>
      </geometry>
    </collision>
    <inertial>
      <mass value="1.0"/>
      <inertia ixx="0.01" ixy="0.0" ixz="0.0" iyy="0.01" iyz="0.0" izz="0.01"/>
    </inertial>
  </link>

  <!-- Joint 2 -->
  <joint name="joint2" type="revolute">
    <parent link="link1"/>
    <child link="link2"/>
    <origin xyz="0 0 0" rpy="0 0 0"/>
    <axis xyz="0 0 1"/>
    <limit lower="-1.57" upper="1.57" effort="10.0" velocity="1.0"/>
  </joint>

  <!-- Link 3 -->
  <link name="link3">
    <visual>
    <origin xyz="0 0 0.25" rpy="0 0 0" />
      <geometry>
        <box size="0.1 0.1 0.5"/>
      </geometry>
      <material name="green">
        <color rgba="0 1 0 1"/>
      </material>
    </visual>
    <collision>
      <geometry>
        <box size="0.1 0.1 0.5"/>
      </geometry>
    </collision>
    <inertial>
      <mass value="1.0"/>
      <inertia ixx="0.01" ixy="0.0" ixz="0.0" iyy="0.01" iyz="0.0" izz="0.01"/>
    </inertial>
  </link>

  <!-- Joint 3 -->
  <joint name="joint3" type="prismatic">
    <parent link="link2"/>
    <child link="link3"/>
    <origin xyz="0 0 0.5" rpy="-1.57 0 0"/>
    <axis xyz="0 0 1"/>
    <limit lower="0.0" upper="1.0" effort="10.0" velocity="0.5"/>
  </joint>

</robot>
